<mujoco model="Humanoid and 100 objects">
    <compiler angle='radian' meshdir="../mesh/ur5/"/>

    <option timestep="0.003" iterations="50" solver="Newton" jacobian="sparse" cone="elliptic" tolerance="1e-10"/>

    <size njmax="5000" nconmax="2000" nstack="5000000"/>

    <default>
        <geom solimp=".9 .9 .01"/>        

        <default class="humanoid">
            <geom material="humanoid"/>        
            <joint damping="1" limited="true"/>
        </default>

        <default class="object1">
            <geom type="capsule" material="object1" size="0.1 0.05"/>
        </default>

        <default class="object2">
            <geom type="ellipsoid" material="object2" size="0.15 0.1 0.07"/>
        </default>

        <default class="object3">
            <geom type="box" material="object3" size="0.15 0.1 0.05"/>
        </default>

        <default class="object4">
            <geom type="cylinder" material="object4" size="0.1 0.05" condim="4" friction="1 .01 .01"/>
        </default>

        <default class="object5">
            <geom type="sphere" material="object5" size="0.1"/>
        </default>

        <default class="border">
            <geom type="capsule" size="0.4" rgba=".4 .4 .4 1"/>
        </default>

        <default class="borderpost">
            <geom type="box" size="0.41 0.41 0.41" rgba=".55 .55 .55 1"/>
        </default>
    </default>

    <asset>
        <mesh file="base.stl" scale = "2 2 2"/>
        <mesh file="shoulder.stl" scale = "2 2 2"/>
        <mesh file="upperarm.stl" scale = "2 2 2"/>
        <mesh file="forearm.stl" scale = "2 2 2"/>
        <mesh file="wrist1.stl" scale = "2 2 2"/>
        <mesh file="wrist2.stl" scale = "2 2 2"/>
        <mesh file="wrist3.stl" scale = "2 2 2"/>
        <mesh file="kinova_robotiq_coupler.stl" />
        <mesh file="robotiq_85_base_link.stl" />
        <mesh file="robotiq_85_finger_link.stl" />
        <mesh file="robotiq_85_finger_tip_link.stl" />
        <mesh file="robotiq_85_inner_knuckle_link.stl" />
        <mesh file="robotiq_85_knuckle_link.stl" />
        <material name="RobMat" specular="0.9" shininess="0.5" reflectance="0" rgba="0.7 0.7 0.7 1" emission="0.1" />
        <material name="GriMat" specular="0.9" shininess="0.5" reflectance="0" rgba="0.1 0.1 0.1 1" emission="0.1" />
        <material name="BasketMat" specular="0" shininess="0" reflectance="0" rgba="0.26 0.16 0.16796875 1" emission="0" />
        <texture type="skybox" builtin="gradient" width="128" height="128" rgb1=".4 .6 .8" rgb2="0 0 0"/>  
        <texture name="texgeom" type="cube" builtin="flat" mark="cross" width="128" height="128" 
            rgb1="0.6 0.6 0.6" rgb2="0.6 0.6 0.6" markrgb="1 1 1"/>  
        <texture name="texplane" type="2d" builtin="checker" rgb1=".4 .4 .4" rgb2=".6 .6 .6" 
            width="512" height="512"/>  
        <material name='MatPlane' reflectance='0.3' texture="texplane" texrepeat="1 1" texuniform="true"/>
        <material name='humanoid' texture="texgeom" texuniform="true" rgba="1.2 1.2 0.6 1"/>
        <material name='object1' texture="texgeom" texuniform="true" rgba=".4 .9 .6 1" />
        <material name='object2' texture="texgeom" texuniform="true" rgba=".4 .6 .9 1" />
        <material name='object3' texture="texgeom" texuniform="true" rgba=".4 .9 .9 1" />
        <material name='object4' texture="texgeom" texuniform="true" rgba=".8 .6 .8 1" />
        <material name='object5' texture="texgeom" texuniform="true" rgba=".9 .1 .1 1" />
    </asset>

    <visual>
        <quality shadowsize="4096" offsamples="8"/>
        <map znear="0.1" force="0.05"/>
    </visual>

    <statistic extent="4"/>

    <worldbody>
        <light directional="true" diffuse=".8 .8 .8" pos="0 0 10" dir="0 0 -10"/>

        <geom pos="0 0 0" type="plane" size="3 3 .5" rgba=".7 .7 .7 1" material="MatPlane"/>
       
        <geom class="border" fromto="-3 3 0 3 3 0"  />
        <geom class="border" fromto="-3 -3 0 3 -3 0"  />
        <geom class="border" fromto="3 3 0 3 -3 0"  />
        <geom class="border" fromto="-3 3 0 -3 -3 0"  />
        <geom class="borderpost" pos="3 3 0"/>
        <geom class="borderpost" pos="-3 3 0"/>
        <geom class="borderpost" pos="3 -3 0"/>
        <geom class="borderpost" pos="-3 -3 0"/>

        <body name="base_link" pos="0 0 2.8" quat="0.3826834324 0 0 0.9238795325" >
            <inertial pos="0 0 0" quat="0.5 0.5 -0.5 0.5" mass="4" diaginertia="0.0072 0.00443333 0.00443333" />
            <geom name="base_mesh" type="mesh" mesh="base" material="RobMat"  />

            <body name="shoulder_link" pos="0 0 0.1783">
                <inertial pos="0 0 0" mass="3.7" diaginertia="0.0102675 0.0102675 0.00666" />
                <geom name="shoulder_mesh" type="mesh" mesh="shoulder" material="RobMat"  />
                <joint name="joint1" pos="0 0 0" axis="0 0 1" range="0 2.967059728"/>

                <body name="upper_arm_link" pos="0 0.2717 0" quat="0.707107 0 0.707107 0">
                    <inertial pos="0 0 0.28" mass="8.393" diaginertia="0.226891 0.226891 0.0151074" />
                    <geom name="upperarm_mesh" type="mesh" mesh="upperarm" material="RobMat" />
                    <joint name="joint2" pos="0 0 0" axis="0 1 0" range="0 2.967059728"/>

                    <body name="forearm_link" pos="0 -0.24 0.95">
                        <inertial pos="0 0 0.25" mass="2.275" diaginertia="0.0494433 0.0494433 0.004095" />
                        <geom name="forearm_mesh" type="mesh" mesh="forearm" material="RobMat" />

                        <!--camera name="forearm_camera" pos="0 0.1 0.07" euler="3.14159265 0 1.570796" /-->


                        <joint name="joint3" pos="0 0 0" axis="0 1 0" range="0 2.967059728"/>

                        <body name="wrist1_link" pos="0 0 0.40" quat="0.707107 0 0.707107 0">
                            <inertial pos="0 0 0" quat="0.5 0.5 -0.5 0.5" mass="1.219" diaginertia="0.21942 0.111173 0.111173" />
                            <geom name="wrist1_mesh" type="mesh" mesh="wrist1" material="RobMat" />
                            <joint name="joint4" pos="0 0 0" axis="0 1 0" range="0 2.967059728"/>

                            <body name="wrist2_link" pos="0 0.186 0">
                                <inertial pos="0 0 0" quat="0.5 0.5 -0.5 0.5" mass="1.219" diaginertia="0.21942 0.111173 0.111173" />
                                <geom name="wrist2_mesh" type="mesh" mesh="wrist2" material="RobMat" />
                                <joint name="joint5" pos="0 0 0" axis="0 0 1" range="0 2.967059728"/>

                                <body name="wrist3_link" pos="0 0 0.1893" quat="0.707107 0 -0.707107 0" >
                                    <inertial pos="0 0 0" quat="0.5 0.5 -0.5 0.5" mass="0.1879" diaginertia="0.033822 0.0171365 0.0171365" />
                                    <geom name="wrist3_mesh" type="mesh" mesh="wrist3" material="RobMat" contype="1" conaffinity="1" />
                                    <joint name="joint6" pos="0 0 0" axis="0 1 0" range="0 2.967059728"/>

                                    <body name="ee_link" pos="0 0.1646 0" quat="0.707107 -0.707107 0 0">
                                        <inertial pos="0 0.0823 0" quat="0.707107 -0.707107 0 0" mass="0" diaginertia="0 0 0" />

                                        <!--camera name="gripper_camera" euler="0 3.14159265 0" fovy="63.5" /-->
                                        <geom name="kinova_robotiq_coupler_mesh" type="mesh" mesh="kinova_robotiq_coupler" pos="0 0 0.0932" material="GriMat" />
                                        <geom name="robotiq_85_base_link_mesh" type="mesh" mesh="robotiq_85_base_link" pos="0 0 0.0032" quat="0.707107 0 -0.707107 0" material="GriMat" />

                                        <body name="right_driver" pos="0 -0.0606011 0.104904" quat="0.707107 0 -0.707107 0">
                                            <geom name="right_driver_mesh" type="mesh" mesh="robotiq_85_knuckle_link" material="GriMat" contype="0" conaffinity="0" />
                                            <joint name="joint7_1" axis="0 0 1" type="hinge" limited="true" range="0 0.872664626" />

                                        
                                            <body name="right_coupler" pos="0 -0.0615 0">
                                                <geom name="right_coupler_mesh" type="mesh" mesh="robotiq_85_finger_link" material="GriMat" contype="0" conaffinity="0" />
                                                <joint name="joint8_1" axis="0 0 1" type="hinge" limited="true" range="0 2.967059728" />

                                                <body name="right_follower_link" pos="0.095 -0.012 0">
                                                    <geom name="right_follower_mesh" pos="0.005 0.042 0" type="mesh" mesh="robotiq_85_finger_tip_link" material="GriMat" />
                                                    <joint name="joint9_1" axis="0 0 1" type="hinge" limited="true" range="0 2.967059728" />
                                                </body>

                                            </body>

                                        </body>

                                        <body name="right_spring_link" pos="0.0016 -0.012 0.0614" quat="0.707107 0 -0.707107 0">
                                            <geom name="right_spring_mesh" type="mesh" pos="0 -0.0005 0.0016" mesh="robotiq_85_inner_knuckle_link" material="GriMat" contype="0" conaffinity="0" />
                                            <joint name="joint10_1" axis="0 0 1" type="hinge" limited="true" range="0 1" />
                                        </body>


                                        <body name="left_driver" pos="0 0.0606011 0.104904" quat="0 0.707107 0 0.707107">
                                            <geom name="left_driver_mesh" type="mesh" mesh="robotiq_85_knuckle_link" material="GriMat" contype="0" conaffinity="0" />
                                            <joint name="joint7_2" axis="0 0 1" type="hinge" limited="true" range="0 0.872664626" />

                                        
                                            <body name="left_coupler" pos="0 -0.0615 0">
                                                <geom name="left_coupler_mesh" type="mesh" mesh="robotiq_85_finger_link" material="GriMat" contype="0" conaffinity="0" />
                                                <joint name="joint8_2" axis="0 0 1" type="hinge" limited="true" range="0 2.967059728" />

                                                <body name="left_follower_link" pos="0.0875 -0.012 0">
                                                    <geom name="left_follower_mesh" pos="0.005 0.042 0" type="mesh" mesh="robotiq_85_finger_tip_link" material="GriMat" />
                                                    <joint name="joint9_2" axis="0 0 1" type="hinge" limited="true" range="0 2.967059728" />
                                                </body>

                                            </body>

                                        </body>

                                        <body name="left_spring_link" pos="0.0032 0.024 0.1214" quat="0 0.707107 0 0.707107">
                                            <geom name="left_spring_mesh" type="mesh" pos="0 0.0010 0.0032" mesh="robotiq_85_inner_knuckle_link" material="GriMat" contype="0" conaffinity="0" />
                                            <joint name="joint10_2" axis="0 0 1" type="hinge" limited="true" range="0 1" />
                                        </body>

                                    </body>
                                </body>
                            </body>
                        </body>
                    </body>
                </body>
            </body>
        </body>

        <body pos="-2 -2 1" quat="-0.632456 -0.632456 0.316228 0.316228">
            <freejoint/>
            <geom class="object1"/>
        </body>
        <body pos="-2 -2 2" quat="-0.5547 -0.5547 0.5547 0.27735">
            <freejoint/>
            <geom class="object1"/>
        </body>
        <body pos="-2 -2 3" quat="-0.471405 -0.471405 0.707107 0.235702">
            <freejoint/>
            <geom class="object1"/>
        </body>
        <body pos="-2 -2 4" quat="-0.471405 -0.471405 0.707107 0.235702">
            <freejoint/>
            <geom class="object1"/>
        </body>

        <body pos="-2 -1 1" quat="-0.755929 -0.377964 0.377964 0.377964">
            <freejoint/>
            <geom class="object1"/>
        </body>
        <body pos="-2 -1 2" quat="-0.632456 -0.316228 0.632456 0.316228">
            <freejoint/>
            <geom class="object1"/>
        </body>
        <body pos="-2 -1 3" quat="-0.516398 -0.258199 0.774597 0.258199">
            <freejoint/>
            <geom class="object1"/>
        </body>
        <body pos="-2 -1 4" quat="-0.516398 -0.258199 0.774597 0.258199">
            <freejoint/>
            <geom class="object1"/>
        </body>

        <body pos="-2 0 1" quat="-0.816497 0 0.408248 0.408248">
            <freejoint/>
            <geom class="object1"/>
        </body>
        <body pos="-2 0 2" quat="-0.666667 0 0.666667 0.333333">
            <freejoint/>
            <geom class="object1"/>
        </body>
        <body pos="-2 0 3" quat="-0.534522 0 0.801784 0.267261">
            <freejoint/>
            <geom class="object1"/>
        </body>
        <body pos="-2 0 4" quat="-0.534522 0 0.801784 0.267261">
            <freejoint/>
            <geom class="object1"/>
        </body>

        <body pos="-2 1 1" quat="-0.755929 0.377964 0.377964 0.377964">
            <freejoint/>
            <geom class="object1"/>
        </body>
        <body pos="-2 1 2" quat="-0.632456 0.316228 0.632456 0.316228">
            <freejoint/>
            <geom class="object1"/>
        </body>
        <body pos="-2 1 3" quat="-0.516398 0.258199 0.774597 0.258199">
            <freejoint/>
            <geom class="object1"/>
        </body>
        <body pos="-2 1 4" quat="-0.516398 0.258199 0.774597 0.258199">
            <freejoint/>
            <geom class="object1"/>
        </body>

        <body pos="-2 2 1" quat="-0.632456 0.632456 0.316228 0.316228">
            <freejoint/>
            <geom class="object1"/>
        </body>
        <body pos="-2 2 2" quat="-0.5547 0.5547 0.5547 0.27735">
            <freejoint/>
            <geom class="object1"/>
        </body>
        <body pos="-2 2 3" quat="-0.471405 0.471405 0.707107 0.235702">
            <freejoint/>
            <geom class="object1"/>
        </body>
        <body pos="-2 2 4" quat="-0.471405 0.471405 0.707107 0.235702">
            <freejoint/>
            <geom class="object1"/>
        </body>

        <body pos="-1 -2 1" quat="-0.377964 -0.755929 0.377964 0.377964">
            <freejoint/>
            <geom class="object2"/>
        </body>
        <body pos="-1 -2 2" quat="-0.316228 -0.632456 0.632456 0.316228">
            <freejoint/>
            <geom class="object2"/>
        </body>
        <body pos="-1 -2 3" quat="-0.258199 -0.516398 0.774597 0.258199">
            <freejoint/>
            <geom class="object2"/>
        </body>
        <body pos="-1 -2 4" quat="-0.258199 -0.516398 0.774597 0.258199">
            <freejoint/>
            <geom class="object2"/>
        </body>

        <body pos="-1 -1 1" quat="-0.5 -0.5 0.5 0.5">
            <freejoint/>
            <geom class="object2"/>
        </body>
        <body pos="-1 -1 2" quat="-0.377964 -0.377964 0.755929 0.377964">
            <freejoint/>
            <geom class="object2"/>
        </body>
        <body pos="-1 -1 3" quat="-0.288675 -0.288675 0.866025 0.288675">
            <freejoint/>
            <geom class="object2"/>
        </body>
        <body pos="-1 -1 4" quat="-0.288675 -0.288675 0.866025 0.288675">
            <freejoint/>
            <geom class="object2"/>
        </body>

        <body pos="-1 0 1" quat="-0.57735 0 0.57735 0.57735">
            <freejoint/>
            <geom class="object2"/>
        </body>
        <body pos="-1 0 2" quat="-0.408248 0 0.816497 0.408248">
            <freejoint/>
            <geom class="object2"/>
        </body>
        <body pos="-1 0 3" quat="-0.301511 0 0.904534 0.301511">
            <freejoint/>
            <geom class="object2"/>
        </body>
        <body pos="-1 0 4" quat="-0.301511 0 0.904534 0.301511">
            <freejoint/>
            <geom class="object2"/>
        </body>

        <body pos="-1 1 1" quat="-0.5 0.5 0.5 0.5">
            <freejoint/>
            <geom class="object2"/>
        </body>
        <body pos="-1 1 2" quat="-0.377964 0.377964 0.755929 0.377964">
            <freejoint/>
            <geom class="object2"/>
        </body>
        <body pos="-1 1 3" quat="-0.288675 0.288675 0.866025 0.288675">
            <freejoint/>
            <geom class="object2"/>
        </body>
        <body pos="-1 1 4" quat="-0.288675 0.288675 0.866025 0.288675">
            <freejoint/>
            <geom class="object2"/>
        </body>

        <body pos="-1 2 1" quat="-0.377964 0.755929 0.377964 0.377964">
            <freejoint/>
            <geom class="object2"/>
        </body>
        <body pos="-1 2 2" quat="-0.316228 0.632456 0.632456 0.316228">
            <freejoint/>
            <geom class="object2"/>
        </body>
        <body pos="-1 2 3" quat="-0.258199 0.516398 0.774597 0.258199">
            <freejoint/>
            <geom class="object2"/>
        </body>
        <body pos="-1 2 4" quat="-0.258199 0.516398 0.774597 0.258199">
            <freejoint/>
            <geom class="object2"/>
        </body>

        <body pos="0 -2 1" quat="0 -0.816497 0.408248 0.408248">
            <freejoint/>
            <geom class="object3"/>
        </body>
        <body pos="0 -2 2" quat="0 -0.666667 0.666667 0.333333">
            <freejoint/>
            <geom class="object3"/>
        </body>
        <body pos="0 -2 3" quat="0 -0.534522 0.801784 0.267261">
            <freejoint/>
            <geom class="object3"/>
        </body>
        <body pos="0 -2 4" quat="0 -0.534522 0.801784 0.267261">
            <freejoint/>
            <geom class="object3"/>
        </body>

        <body pos="0 -1 1" quat="0 -0.57735 0.57735 0.57735">
            <freejoint/>
            <geom class="object3"/>
        </body>
        <body pos="0 -1 2" quat="0 -0.408248 0.816497 0.408248">
            <freejoint/>
            <geom class="object3"/>
        </body>
        <body pos="0 -1 3" quat="0 -0.301511 0.904534 0.301511">
            <freejoint/>
            <geom class="object3"/>
        </body>
        <body pos="0 -1 4" quat="0 -0.301511 0.904534 0.301511">
            <freejoint/>
            <geom class="object3"/>
        </body>

        <body pos="0.3 0 1" quat="0 0 0.707107 0.707107">
            <freejoint/>
            <geom class="object3"/>
        </body>
        <body pos="0 0 2" quat="0 0 0.894427 0.447214">
            <freejoint/>
            <geom class="object3"/>
        </body>
        <body pos="0 0 3" quat="0 0 0.948683 0.316228">
            <freejoint/>
            <geom class="object3"/>
        </body>
        <body pos="0 0 4" quat="0 0 0.948683 0.316228">
            <freejoint/>
            <geom class="object3"/>
        </body>

        <body pos="0 1 1" quat="0 0.57735 0.57735 0.57735">
            <freejoint/>
            <geom class="object3"/>
        </body>
        <body pos="0 1 2" quat="0 0.408248 0.816497 0.408248">
            <freejoint/>
            <geom class="object3"/>
        </body>
        <body pos="0 1 3" quat="0 0.301511 0.904534 0.301511">
            <freejoint/>
            <geom class="object3"/>
        </body>
        <body pos="0 1 4" quat="0 0.301511 0.904534 0.301511">
            <freejoint/>
            <geom class="object3"/>
        </body>

        <body pos="0 2 1" quat="0 0.816497 0.408248 0.408248">
            <freejoint/>
            <geom class="object3"/>
        </body>
        <body pos="0 2 2" quat="0 0.666667 0.666667 0.333333">
            <freejoint/>
            <geom class="object3"/>
        </body>
        <body pos="0 2 3" quat="0 0.534522 0.801784 0.267261">
            <freejoint/>
            <geom class="object3"/>
        </body>
        <body pos="0 2 4" quat="0 0.534522 0.801784 0.267261">
            <freejoint/>
            <geom class="object3"/>
        </body>

        <body pos="1 -2 1" quat="0.377964 -0.755929 0.377964 0.377964">
            <freejoint/>
            <geom class="object4"/>
        </body>
        <body pos="1 -2 2" quat="0.316228 -0.632456 0.632456 0.316228">
            <freejoint/>
            <geom class="object4"/>
        </body>
        <body pos="1 -2 3" quat="0.258199 -0.516398 0.774597 0.258199">
            <freejoint/>
            <geom class="object4"/>
        </body>
        <body pos="1 -2 4" quat="0.258199 -0.516398 0.774597 0.258199">
            <freejoint/>
            <geom class="object4"/>
        </body>

        <body pos="1 -1 1" quat="0.5 -0.5 0.5 0.5">
            <freejoint/>
            <geom class="object4"/>
        </body>
        <body pos="1 -1 2" quat="0.377964 -0.377964 0.755929 0.377964">
            <freejoint/>
            <geom class="object4"/>
        </body>
        <body pos="1 -1 3" quat="0.288675 -0.288675 0.866025 0.288675">
            <freejoint/>
            <geom class="object4"/>
        </body>
        <body pos="1 -1 4" quat="0.288675 -0.288675 0.866025 0.288675">
            <freejoint/>
            <geom class="object4"/>
        </body>

        <body pos="1 0 1" quat="0.57735 0 0.57735 0.57735">
            <freejoint/>
            <geom class="object4"/>
        </body>
        <body pos="1 0 2" quat="0.408248 0 0.816497 0.408248">
            <freejoint/>
            <geom class="object4"/>
        </body>
        <body pos="1 0 3" quat="0.301511 0 0.904534 0.301511">
            <freejoint/>
            <geom class="object4"/>
        </body>
        <body pos="1 0 4" quat="0.301511 0 0.904534 0.301511">
            <freejoint/>
            <geom class="object4"/>
        </body>

        <body pos="1 1 1" quat="0.5 0.5 0.5 0.5">
            <freejoint/>
            <geom class="object4"/>
        </body>
        <body pos="1 1 2" quat="0.377964 0.377964 0.755929 0.377964">
            <freejoint/>
            <geom class="object4"/>
        </body>
        <body pos="1 1 3" quat="0.288675 0.288675 0.866025 0.288675">
            <freejoint/>
            <geom class="object4"/>
        </body>
        <body pos="1 1 4" quat="0.288675 0.288675 0.866025 0.288675">
            <freejoint/>
            <geom class="object4"/>
        </body>

        <body pos="1 2 1" quat="0.377964 0.755929 0.377964 0.377964">
            <freejoint/>
            <geom class="object4"/>
        </body>
        <body pos="1 2 2" quat="0.316228 0.632456 0.632456 0.316228">
            <freejoint/>
            <geom class="object4"/>
        </body>
        <body pos="1 2 3" quat="0.258199 0.516398 0.774597 0.258199">
            <freejoint/>
            <geom class="object4"/>
        </body>
        <body pos="1 2 4" quat="0.258199 0.516398 0.774597 0.258199">
            <freejoint/>
            <geom class="object4"/>
        </body>

        <body pos="2 -2 1" quat="0.632456 -0.632456 0.316228 0.316228">
            <freejoint/>
            <geom class="object5"/>
        </body>
        <body pos="2 -2 2" quat="0.5547 -0.5547 0.5547 0.27735">
            <freejoint/>
            <geom class="object5"/>
        </body>
        <body pos="2 -2 3" quat="0.471405 -0.471405 0.707107 0.235702">
            <freejoint/>
            <geom class="object5"/>
        </body>
        <body pos="2 -2 4" quat="0.471405 -0.471405 0.707107 0.235702">
            <freejoint/>
            <geom class="object5"/>
        </body>

        <body pos="2 -1 1" quat="0.755929 -0.377964 0.377964 0.377964">
            <freejoint/>
            <geom class="object5"/>
        </body>
        <body pos="2 -1 2" quat="0.632456 -0.316228 0.632456 0.316228">
            <freejoint/>
            <geom class="object5"/>
        </body>
        <body pos="2 -1 3" quat="0.516398 -0.258199 0.774597 0.258199">
            <freejoint/>
            <geom class="object5"/>
        </body>
        <body pos="2 -1 4" quat="0.516398 -0.258199 0.774597 0.258199">
            <freejoint/>
            <geom class="object5"/>
        </body>

        <body pos="2 0 1" quat="0.816497 0 0.408248 0.408248">
            <freejoint/>
            <geom class="object5"/>
        </body>
        <body pos="2 0 2" quat="0.666667 0 0.666667 0.333333">
            <freejoint/>
            <geom class="object5"/>
        </body>
        <body pos="2 0 3" quat="0.534522 0 0.801784 0.267261">
            <freejoint/>
            <geom class="object5"/>
        </body>
        <body pos="2 0 4" quat="0.534522 0 0.801784 0.267261">
            <freejoint/>
            <geom class="object5"/>
        </body>

        <body pos="2 1 1" quat="0.755929 0.377964 0.377964 0.377964">
            <freejoint/>
            <geom class="object5"/>
        </body>
        <body pos="2 1 2" quat="0.632456 0.316228 0.632456 0.316228">
            <freejoint/>
            <geom class="object5"/>
        </body>
        <body pos="2 1 3" quat="0.516398 0.258199 0.774597 0.258199">
            <freejoint/>
            <geom class="object5"/>
        </body>
        <body pos="2 1 4" quat="0.516398 0.258199 0.774597 0.258199">
            <freejoint/>
            <geom class="object5"/>
        </body>

        <body pos="2 2 1" quat="0.632456 0.632456 0.316228 0.316228">
            <freejoint/>
            <geom class="object5"/>
        </body>
        <body pos="2 2 2" quat="0.5547 0.5547 0.5547 0.27735">
            <freejoint/>
            <geom class="object5"/>
        </body>
        <body pos="2 2 3" quat="0.471405 0.471405 0.707107 0.235702">
            <freejoint/>
            <geom class="object5"/>
        </body>
        <body pos="2 2 4" quat="0.471405 0.471405 0.707107 0.235702">
            <freejoint/>
            <geom class="object5"/>
        </body>
        
    </worldbody>
</mujoco>
